Workbook

Sheet Instructions
A1: DOKI recipe workbook
A2: One sheet per recipe. Weights are grams per 1 kg of meat.
A4: How to use
A5: Open the sheet for a recipe. In the shaded columns type the ingredient name and how many grams of it go into 1 kg of meat. That is all.
A6: Everything to the right calculates itself: the percentage, the target for a typical batch, which scale should weigh it, and the tolerance that scale can actually hold.
A8: What the colours mean
A9: Shaded cells are yours to type in. Everything else is a formula — overwriting one breaks that row.
A10: A red row means neither scale can weigh that ingredient at this batch size. Split it, premix it, or make the batch bigger.
A11: An amber row is fine to run, but the scale's resolution is coarser than the recipe's percentage, so it is held to a looser band. The Note column says so.
A13: Which scale gets what
A14: The floor scale reads in 5 g steps. Two of those have to fit inside the tolerance before it is enforcing anything, so it only handles targets above 500 g — that is 2 × 5 g ÷ 2 %, on the Settings sheet. Everything smaller goes on the bench scale.
A15: Change the tolerance percentage or either scale's division on the Settings sheet and all seven recipes re-evaluate.
... A27: Run python3 xlsx_to_recipes.py DOKI-Recipes.xlsx to turn this workbook into the recipes.json the panel reads. It refuses to write a recipe that still has an unweighable ingredient or an untouched example row.

Sheet Settings
A1: Settings
A2: These drive every recipe sheet. Change a number here and all seven recipes re-evaluate.
A4: Tolerance (percent of target) | B4: 0.02 | C4: What the recipe asks for. The station uses this too.
A6: MAIN SCALE — name | B6: Floor scale
A7: division (g) | B7: 5 | C7: Smallest step it reads. From the RS232 frame resolution.
A8: capacity (g) | B8: 50000
A9: usable (g) | B9: 50000 | C9: Capacity less the tub's tare.
A11: SMALL SCALE — name | B11: Bench scale
A12: division (g) | B12: 0.1 | C12: SPEC NOT CONFIRMED — check the label on the scale.
A13: capacity (g) | B13: 3000 | C13: SPEC NOT CONFIRMED.
A14: usable (g) | B14: 2000 | C14: Capacity less the tare of the container you weigh into.
A17: Crossover — derived | B17: =2*Settings!$B$7/Settings!$B$4 -> 500 | C17: Below this the main scale cannot hold the tolerance: two of its divisions no longer fit inside the percentage.
A18: Crossover — override | C18: Optional. Leave blank to use the derived value. A lower number keeps more ingredients on the floor scale — easier to pour into, looser tolerance, and the recipe sheets say which.
A19: Crossover in force (g) | B19: =IF(B18="",B17,B18) -> 500
A21: Dead zone check | B21: =IF(Settings!$B$14>=Settings!$B$19,"None — the two scales meet","WARNING: nothing can weigh "&TEXT(Settings!$B$14,"#,##0")&" to "&TEXT(Settings!$B$19,"#,##0")&" g") -> None — the two scales meet

Sheet Teriyaki
A1: Teriyaki
A2: Type in the shaded cells only. Weights are GRAMS PER 1 KG OF MEAT. Everything to the right is calculated.
A4: Batch base weight (g) | C4: 3200 | D4: A typical batch. Only the Target / Weigh-on / Tolerance columns use it — the station recomputes them from the meat it actually weighs.
A5: Product ID | C5: teriyaki | D5: Bases this applies to | F5: chicken, pork, beef, mutton, fish
A6: Flour ingredient | D6: Water ingredient
A7: # | B7: Ingredient | C7: g per 1 kg meat | D7: % of meat | E7: Target in this batch | F7: Weigh on | G7: Tolerance ± | H7: Note
A8: =IF($B8="","",1) -> 1 | B8: Teriyaki sauce | C8: 73 | D8: =IF($B8="","",$C8/1000) -> 0.073 | E8: =IF($B8="","",$D8*$C$4) -> 233.6 | F8: =IF($B8="","",IF($E8<=0,"NEITHER — zero",IF($E8>=Settings!$B$19,Settings!$B$6,IF($E8>Settings!$B$14,"NEITHER — over bench capacity",IF($E8>=2*Settings!$B$12,Settings!$B$11,"NEITHER — under bench resolution"))))) -> Bench scale | G8: =IF($B8="","",IF($F8=Settings!$B$6,MAX(2*Settings!$B$7,Settings!$B$4*$E8),IF($F8=Settings!$B$11,MAX(2*Settings!$B$12,Settings!$B$4*$E8),""))) -> 4.672 | H8: =IF($B8="","",IF(LEFT($F8,7)="NEITHER","Cannot be weighed — split it, premix it, or raise the batch size",IF($G8>Settings!$B$4*$E8+0.0001,"Held to the scale's resolution, not "&TEXT(Settings!$B$4,"0%"),"")))
A9: =IF($B9="","",2) -> 2 | B9: Soy sauce | C9: 46.4 | D9: =IF($B9="","",$C9/1000) -> 0.0464 | E9: =IF($B9="","",$D9*$C$4) -> 148.48 | F9: =IF($B9="","",IF($E9<=0,"NEITHER — zero",IF($E9>=Settings!$B$19,Settings!$B$6,IF($E9>Settings!$B$14,"NEITHER — over bench capacity",IF($E9>=2*Settings!$B$12,Settings!$B$11,"NEITHER — under bench resolution"))))) -> Bench scale | G9: =IF($B9="","",IF($F9=Settings!$B$6,MAX(2*Settings!$B$7,Settings!$B$4*$E9),IF($F9=Settings!$B$11,MAX(2*Settings!$B$12,Settings!$B$4*$E9),""))) -> 2.9696 | H9: =IF($B9="","",IF(LEFT($F9,7)="NEITHER","Cannot be weighed — split it, premix it, or raise the batch size",IF($G9>Settings!$B$4*$E9+0.0001,"Held to the scale's resolution, not "&TEXT(Settings!$B$4,"0%"),"")))
A10: =IF($B10="","",3) -> 3 | B10: Honey | C10: 42 | D10: =IF($B10="","",$C10/1000) -> 0.042 | E10: =IF($B10="","",$D10*$C$4) -> 134.4 | F10: =IF($B10="","",IF($E10<=0,"NEITHER — zero",IF($E10>=Settings!$B$19,Settings!$B$6,IF($E10>Settings!$B$14,"NEITHER — over bench capacity",IF($E10>=2*Settings!$B$12,Settings!$B$11,"NEITHER — under bench resolution"))))) -> Bench scale | G10: =IF($B10="","",IF($F10=Settings!$B$6,MAX(2*Settings!$B$7,Settings!$B$4*$E10),IF($F10=Settings!$B$11,MAX(2*Settings!$B$12,Settings!$B$4*$E10),""))) -> 2.688 | H10: =IF($B10="","",IF(LEFT($F10,7)="NEITHER","Cannot be weighed — split it, premix it, or raise the batch size",IF($G10>Settings!$B$4*$E10+0.0001,"Held to the scale's resolution, not "&TEXT(Settings!$B$4,"0%"),"")))
A11: =IF($B11="","",4) -> 4 | B11: Tamarind pulp | C11: 25.4 | D11: =IF($B11="","",$C11/1000) -> 0.0254 | E11: =IF($B11="","",$D11*$C$4) -> 81.28 | F11: =IF($B11="","",IF($E11<=0,"NEITHER — zero",IF($E11>=Settings!$B$19,Settings!$B$6,IF($E11>Settings!$B$14,"NEITHER — over bench capacity",IF($E11>=2*Settings!$B$12,Settings!$B$11,"NEITHER — under bench resolution"))))) -> Bench scale | G11: =IF($B11="","",IF($F11=Settings!$B$6,MAX(2*Settings!$B$7,Settings!$B$4*$E11),IF($F11=Settings!$B$11,MAX(2*Settings!$B$12,Settings!$B$4*$E11),""))) -> 1.6256 | H11: =IF($B11="","",IF(LEFT($F11,7)="NEITHER","Cannot be weighed — split it, premix it, or raise the batch size",IF($G11>Settings!$B$4*$E11+0.0001,"Held to the scale's resolution, not "&TEXT(Settings!$B$4,"0%"),"")))
A12: =IF($B12="","",5) -> 5 | B12: White vinegar | C12: 25.4 | D12: =IF($B12="","",$C12/1000) -> 0.0254 | E12: =IF($B12="","",$D12*$C$4) -> 81.28 | F12: =IF($B12="","",IF($E12<=0,"NEITHER — zero",IF($E12>=Settings!$B$19,Settings!$B$6,IF($E12>Settings!$B$14,"NEITHER — over bench capacity",IF($E12>=2*Settings!$B$12,Settings!$B$11,"NEITHER — under bench resolution"))))) -> Bench scale | G12: =IF($B12="","",IF($F12=Settings!$B$6,MAX(2*Settings!$B$7,Settings!$B$4*$E12),IF($F12=Settings!$B$11,MAX(2*Settings!$B$12,Settings!$B$4*$E12),""))) -> 1.6256 | H12: =IF($B12="","",IF(LEFT($F12,7)="NEITHER","Cannot be weighed — split it, premix it, or raise the batch size",IF($G12>Settings!$B$4*$E12+0.0001,"Held to the scale's resolution, not "&TEXT(Settings!$B$4,"0%"),"")))
A13: =IF($B13="","",6) -> 6 | B13: Jaggery powder | C13: 23.2 | D13: =IF($B13="","",$C13/1000) -> 0.0232 | E13: =IF($B13="","",$D13*$C$4) -> 74.24 | F13: =IF($B13="","",IF($E13<=0,"NEITHER — zero",IF($E13>=Settings!$B$19,Settings!$B$6,IF($E13>Settings!$B$14,"NEITHER — over bench capacity",IF($E13>=2*Settings!$B$12,Settings!$B$11,"NEITHER — under bench resolution"))))) -> Bench scale | G13: =IF($B13="","",IF($F13=Settings!$B$6,MAX(2*Settings!$B$7,Settings!$B$4*$E13),IF($F13=Settings!$B$11,MAX(2*Settings!$B$12,Settings!$B$4*$E13),""))) -> 1.4848 | H13: =IF($B13="","",IF(LEFT($F13,7)="NEITHER","Cannot be weighed — split it, premix it, or raise the batch size",IF($G13>Settings!$B$4*$E13+0.0001,"Held to the scale's resolution, not "&TEXT(Settings!$B$4,"0%"),"")))
A14: =IF($B14="","",7) -> 7 | B14: Sea salt | C14: 7.5 | D14: =IF($B14="","",$C14/1000) -> 0.0075 | E14: =IF($B14="","",$D14*$C$4) -> 24 | F14: =IF($B14="","",IF($E14<=0,"NEITHER — zero",IF($E14>=Settings!$B$19,Settings!$B$6,IF($E14>Settings!$B$14,"NEITHER — over bench capacity",IF($E14>=2*Settings!$B$12,Settings!$B$11,"NEITHER — under bench resolution"))))) -> Bench scale | G14: =IF($B14="","",IF($F14=Settings!$B$6,MAX(2*Settings!$B$7,Settings!$B$4*$E14),IF($F14=Settings!$B$11,MAX(2*Settings!$B$12,Settings!$B$4*$E14),""))) -> 0.48 | H14: =IF($B14="","",IF(LEFT($F14,7)="NEITHER","Cannot be weighed — split it, premix it, or raise the batch size",IF($G14>Settings!$B$4*$E14+0.0001,"Held to the scale's resolution, not "&TEXT(Settings!$B$4,"0%"),"")))
A15: =IF($B15="","",8) -> 8 | B15: Sesame seed | C15: 4.5 | D15: =IF($B15="","",$C15/1000) -> 0.0045 | E15: =IF($B15="","",$D15*$C$4) -> 14.4 | F15: =IF($B15="","",IF($E15<=0,"NEITHER — zero",IF($E15>=Settings!$B$19,Settings!$B$6,IF($E15>Settings!$B$14,"NEITHER — over bench capacity",IF($E15>=2*Settings!$B$12,Settings!$B$11,"NEITHER — under bench resolution"))))) -> Bench scale | G15: =IF($B15="","",IF($F15=Settings!$B$6,MAX(2*Settings!$B$7,Settings!$B$4*$E15),IF($F15=Settings!$B$11,MAX(2*Settings!$B$12,Settings!$B$4*$E15),""))) -> 0.288 | H15: =IF($B15="","",IF(LEFT($F15,7)="NEITHER","Cannot be weighed — split it, premix it, or raise the batch size",IF($G15>Settings!$B$4*$E15+0.0001,"Held to the scale's resolution, not "&TEXT(Settings!$B$4,"0%"),"")))
A16: =IF($B16="","",9) -> 9 | B16: Verdad | C16: 2 | D16: =IF($B16="","",$C16/1000) -> 0.002 | E16: =IF($B16="","",$D16*$C$4) -> 6.4 | F16: =IF($B16="","",IF($E16<=0,"NEITHER — zero",IF($E16>=Settings!$B$19,Settings!$B$6,IF($E16>Settings!$B$14,"NEITHER — over bench capacity",IF($E16>=2*Settings!$B$12,Settings!$B$11,"NEITHER — under bench resolution"))))) -> Bench scale | G16: =IF($B16="","",IF($F16=Settings!$B$6,MAX(2*Settings!$B$7,Settings!$B$4*$E16),IF($F16=Settings!$B$11,MAX(2*Settings!$B$12,Settings!$B$4*$E16),""))) -> 0.2 | H16: =IF($B16="","",IF(LEFT($F16,7)="NEITHER","Cannot be weighed — split it, premix it, or raise the batch size",IF($G16>Settings!$B$4*$E16+0.0001,"Held to the scale's resolution, not "&TEXT(Settings!$B$4,"0%"),""))) -> Held to the scale's resolution, not 2%
A17: =IF($B17="","",10) -> 10 | B17: Onion powder | C17: 1.4 | D17: =IF($B17="","",$C17/1000) -> 0.0014 | E17: =IF($B17="","",$D17*$C$4) -> 4.48 | F17: =IF($B17="","",IF($E17<=0,"NEITHER — zero",IF($E17>=Settings!$B$19,Settings!$B$6,IF($E17>Settings!$B$14,"NEITHER — over bench capacity",IF($E17>=2*Settings!$B$12,Settings!$B$11,"NEITHER — under bench resolution"))))) -> Bench scale | G17: =IF($B17="","",IF($F17=Settings!$B$6,MAX(2*Settings!$B$7,Settings!$B$4*$E17),IF($F17=Settings!$B$11,MAX(2*Settings!$B$12,Settings!$B$4*$E17),""))) -> 0.2 | H17: =IF($B17="","",IF(LEFT($F17,7)="NEITHER","Cannot be weighed — split it, premix it, or raise the batch size",IF($G17>Settings!$B$4*$E17+0.0001,"Held to the scale's resolution, not "&TEXT(Settings!$B$4,"0%"),""))) -> Held to the scale's resolution, not 2%
A18: =IF($B18="","",11) -> 11 | B18: Chilli flake | C18: 1.3 | D18: =IF($B18="","",$C18/1000) -> 0.0013 | E18: =IF($B18="","",$D18*$C$4) -> 4.16 | F18: =IF($B18="","",IF($E18<=0,"NEITHER — zero",IF($E18>=Settings!$B$19,Settings!$B$6,IF($E18>Settings!$B$14,"NEITHER — over bench capacity",IF($E18>=2*Settings!$B$12,Settings!$B$11,"NEITHER — under bench resolution"))))) -> Bench scale | G18: =IF($B18="","",IF($F18=Settings!$B$6,MAX(2*Settings!$B$7,Settings!$B$4*$E18),IF($F18=Settings!$B$11,MAX(2*Settings!$B$12,Settings!$B$4*$E18),""))) -> 0.2 | H18: =IF($B18="","",IF(LEFT($F18,7)="NEITHER","Cannot be weighed — split it, premix it, or raise the batch size",IF($G18>Settings!$B$4*$E18+0.0001,"Held to the scale's resolution, not "&TEXT(Settings!$B$4,"0%"),""))) -> Held to the scale's resolution, not 2%
A19: =IF($B19="","",12) -> 12 | B19: Black pepper | C19: 1.1 | D19: =IF($B19="","",$C19/1000) -> 0.0011 | E19: =IF($B19="","",$D19*$C$4) -> 3.52 | F19: =IF($B19="","",IF($E19<=0,"NEITHER — zero",IF($E19>=Settings!$B$19,Settings!$B$6,IF($E19>Settings!$B$14,"NEITHER — over bench capacity",IF($E19>=2*Settings!$B$12,Settings!$B$11,"NEITHER — under bench resolution"))))) -> Bench scale | G19: =IF($B19="","",IF($F19=Settings!$B$6,MAX(2*Settings!$B$7,Settings!$B$4*$E19),IF($F19=Settings!$B$11,MAX(2*Settings!$B$12,Settings!$B$4*$E19),""))) -> 0.2 | H19: =IF($B19="","",IF(LEFT($F19,7)="NEITHER","Cannot be weighed — split it, premix it, or raise the batch size",IF($G19>Settings!$B$4*$E19+0.0001,"Held to the scale's resolution, not "&TEXT(Settings!$B$4,"0%"),""))) -> Held to the scale's resolution, not 2%
A20: =IF($B20="","",13) -> 13 | B20: Yeast extract | C20: 1 | D20: =IF($B20="","",$C20/1000) -> 0.001 | E20: =IF($B20="","",$D20*$C$4) -> 3.2 | F20: =IF($B20="","",IF($E20<=0,"NEITHER — zero",IF($E20>=Settings!$B$19,Settings!$B$6,IF($E20>Settings!$B$14,"NEITHER — over bench capacity",IF($E20>=2*Settings!$B$12,Settings!$B$11,"NEITHER — under bench resolution"))))) -> Bench scale | G20: =IF($B20="","",IF($F20=Settings!$B$6,MAX(2*Settings!$B$7,Settings!$B$4*$E20),IF($F20=Settings!$B$11,MAX(2*Settings!$B$12,Settings!$B$4*$E20),""))) -> 0.2 | H20: =IF($B20="","",IF(LEFT($F20,7)="NEITHER","Cannot be weighed — split it, premix it, or raise the batch size",IF($G20>Settings!$B$4*$E20+0.0001,"Held to the scale's resolution, not "&TEXT(Settings!$B$4,"0%"),""))) -> Held to the scale's resolution, not 2%
A21: =IF($B21="","",14) -> 14 | B21: Garlic powder | C21: 0.6 | D21: =IF($B21="","",$C21/1000) -> 0.0006 | E21: =IF($B21="","",$D21*$C$4) -> 1.92 | F21: =IF($B21="","",IF($E21<=0,"NEITHER — zero",IF($E21>=Settings!$B$19,Settings!$B$6,IF($E21>Settings!$B$14,"NEITHER — over bench capacity",IF($E21>=2*Settings!$B$12,Settings!$B$11,"NEITHER — under bench resolution"))))) -> Bench scale | G21: =IF($B21="","",IF($F21=Settings!$B$6,MAX(2*Settings!$B$7,Settings!$B$4*$E21),IF($F21=Settings!$B$11,MAX(2*Settings!$B$12,Settings!$B$4*$E21),""))) -> 0.2 | H21: =IF($B21="","",IF(LEFT($F21,7)="NEITHER","Cannot be weighed — split it, premix it, or raise the batch size",IF($G21>Settings!$B$4*$E21+0.0001,"Held to the scale's resolution, not "&TEXT(Settings!$B$4,"0%"),""))) -> Held to the scale's resolution, not 2%
A22: =IF($B22="","",15) -> 15 | B22: Bhut jholokia | C22: 0.25 | D22: =IF($B22="","",$C22/1000) -> 0.00025 | E22: =IF($B22="","",$D22*$C$4) -> 0.8 | F22: =IF($B22="","",IF($E22<=0,"NEITHER — zero",IF($E22>=Settings!$B$19,Settings!$B$6,IF($E22>Settings!$B$14,"NEITHER — over bench capacity",IF($E22>=2*Settings!$B$12,Settings!$B$11,"NEITHER — under bench resolution"))))) -> Bench scale | G22: =IF($B22="","",IF($F22=Settings!$B$6,MAX(2*Settings!$B$7,Settings!$B$4*$E22),IF($F22=Settings!$B$11,MAX(2*Settings!$B$12,Settings!$B$4*$E22),""))) -> 0.2 | H22: =IF($B22="","",IF(LEFT($F22,7)="NEITHER","Cannot be weighed — split it, premix it, or raise the batch size",IF($G22>Settings!$B$4*$E22+0.0001,"Held to the scale's resolution, not "&TEXT(Settings!$B$4,"0%"),""))) -> Held to the scale's resolution, not 2%
A23: =IF($B23="","",16) -> 16 | B23: Liquid smoke | C23: 0 | D23: =IF($B23="","",$C23/1000) -> 0 | E23: =IF($B23="","",$D23*$C$4) -> 0 | F23: =IF($B23="","",IF($E23<=0,"NEITHER — zero",IF($E23>=Settings!$B$19,Settings!$B$6,IF($E23>Settings!$B$14,"NEITHER — over bench capacity",IF($E23>=2*Settings!$B$12,Settings!$B$11,"NEITHER — under bench resolution"))))) -> NEITHER — zero | G23: =IF($B23="","",IF($F23=Settings!$B$6,MAX(2*Settings!$B$7,Settings!$B$4*$E23),IF($F23=Settings!$B$11,MAX(2*Settings!$B$12,Settings!$B$4*$E23),""))) | H23: =IF($B23="","",IF(LEFT($F23,7)="NEITHER","Cannot be weighed — split it, premix it, or raise the batch size",IF($G23>Settings!$B$4*$E23+0.0001,"Held to the scale's resolution, not "&TEXT(Settings!$B$4,"0%"),""))) -> Cannot be weighed — split it, premix it, or raise the batch size
A24: =IF($B24="","",17) | D24: =IF($B24="","",$C24/1000) | E24: =IF($B24="","",$D24*$C$4) | F24: =IF($B24="","",IF($E24<=0,"NEITHER — zero",IF($E24>=Settings!$B$19,Settings!$B$6,IF($E24>Settings!$B$14,"NEITHER — over bench capacity",IF($E24>=2*Settings!$B$12,Settings!$B$11,"NEITHER — under bench resolution"))))) | G24: =IF($B24="","",IF($F24=Settings!$B$6,MAX(2*Settings!$B$7,Settings!$B$4*$E24),IF($F24=Settings!$B$11,MAX(2*Settings!$B$12,Settings!$B$4*$E24),""))) | H24: =IF($B24="","",IF(LEFT($F24,7)="NEITHER","Cannot be weighed — split it, premix it, or raise the batch size",IF($G24>Settings!$B$4*$E24+0.0001,"Held to the scale's resolution, not "&TEXT(Settings!$B$4,"0%"),"")))
A25: =IF($B25="","",18) | D25: =IF($B25="","",$C25/1000) | E25: =IF($B25="","",$D25*$C$4) | F25: =IF($B25="","",IF($E25<=0,"NEITHER — zero",IF($E25>=Settings!$B$19,Settings!$B$6,IF($E25>Settings!$B$14,"NEITHER — over bench capacity",IF($E25>=2*Settings!$B$12,Settings!$B$11,"NEITHER — under bench resolution"))))) | G25: =IF($B25="","",IF($F25=Settings!$B$6,MAX(2*Settings!$B$7,Settings!$B$4*$E25),IF($F25=Settings!$B$11,MAX(2*Settings!$B$12,Settings!$B$4*$E25),""))) | H25: =IF($B25="","",IF(LEFT($F25,7)="NEITHER","Cannot be weighed — split it, premix it, or raise the batch size",IF($G25>Settings!$B$4*$E25+0.0001,"Held to the scale's resolution, not "&TEXT(Settings!$B$4,"0%"),"")))
A26: =IF($B26="","",19) | D26: =IF($B26="","",$C26/1000) | E26: =IF($B26="","",$D26*$C$4) | F26: =IF($B26="","",IF($E26<=0,"NEITHER — zero",IF($E26>=Settings!$B$19,Settings!$B$6,IF($E26>Settings!$B$14,"NEITHER — over bench capacity",IF($E26>=2*Settings!$B$12,Settings!$B$11,"NEITHER — under bench resolution"))))) | G26: =IF($B26="","",IF($F26=Settings!$B$6,MAX(2*Settings!$B$7,Settings!$B$4*$E26),IF($F26=Settings!$B$11,MAX(2*Settings!$B$12,Settings!$B$4*$E26),""))) | H26: =IF($B26="","",IF(LEFT($F26,7)="NEITHER","Cannot be weighed — split it, premix it, or raise the batch size",IF($G26>Settings!$B$4*$E26+0.0001,"Held to the scale's resolution, not "&TEXT(Settings!$B$4,"0%"),"")))
A27: =IF($B27="","",20) | D27: =IF($B27="","",$C27/1000) | E27: =IF($B27="","",$D27*$C$4) | F27: =IF($B27="","",IF($E27<=0,"NEITHER — zero",IF($E27>=Settings!$B$19,Settings!$B$6,IF($E27>Settings!$B$14,"NEITHER — over bench capacity",IF($E27>=2*Settings!$B$12,Settings!$B$11,"NEITHER — under bench resolution"))))) | G27: =IF($B27="","",IF($F27=Settings!$B$6,MAX(2*Settings!$B$7,Settings!$B$4*$E27),IF($F27=Settings!$B$11,MAX(2*Settings!$B$12,Settings!$B$4*$E27),""))) | H27: =IF($B27="","",IF(LEFT($F27,7)="NEITHER","Cannot be weighed — split it, premix it, or raise the batch size",IF($G27>Settings!$B$4*$E27+0.0001,"Held to the scale's resolution, not "&TEXT(Settings!$B$4,"0%"),"")))
A28: =IF($B28="","",21) | D28: =IF($B28="","",$C28/1000) | E28: =IF($B28="","",$D28*$C$4) | F28: =IF($B28="","",IF($E28<=0,"NEITHER — zero",IF($E28>=Settings!$B$19,Settings!$B$6,IF($E28>Settings!$B$14,"NEITHER — over bench capacity",IF($E28>=2*Settings!$B$12,Settings!$B$11,"NEITHER — under bench resolution"))))) | G28: =IF($B28="","",IF($F28=Settings!$B$6,MAX(2*Settings!$B$7,Settings!$B$4*$E28),IF($F28=Settings!$B$11,MAX(2*Settings!$B$12,Settings!$B$4*$E28),""))) | H28: =IF($B28="","",IF(LEFT($F28,7)="NEITHER","Cannot be weighed — split it, premix it, or raise the batch size",IF($G28>Settings!$B$4*$E28+0.0001,"Held to the scale's resolution, not "&TEXT(Settings!$B$4,"0%"),"")))
A29: =IF($B29="","",22) | D29: =IF($B29="","",$C29/1000) | E29: =IF($B29="","",$D29*$C$4) | F29: =IF($B29="","",IF($E29<=0,"NEITHER — zero",IF($E29>=Settings!$B$19,Settings!$B$6,IF($E29>Settings!$B$14,"NEITHER — over bench capacity",IF($E29>=2*Settings!$B$12,Settings!$B$11,"NEITHER — under bench resolution"))))) | G29: =IF($B29="","",IF($F29=Settings!$B$6,MAX(2*Settings!$B$7,Settings!$B$4*$E29),IF($F29=Settings!$B$11,MAX(2*Settings!$B$12,Settings!$B$4*$E29),""))) | H29: =IF($B29="","",IF(LEFT($F29,7)="NEITHER","Cannot be weighed — split it, premix it, or raise the batch size",IF($G29>Settings!$B$4*$E29+0.0001,"Held to the scale's resolution, not "&TEXT(Settings!$B$4,"0%"),"")))
A30: =IF($B30="","",23) | D30: =IF($B30="","",$C30/1000) | E30: =IF($B30="","",$D30*$C$4) | F30: =IF($B30="","",IF($E30<=0,"NEITHER — zero",IF($E30>=Settings!$B$19,Settings!$B$6,IF($E30>Settings!$B$14,"NEITHER — over bench capacity",IF($E30>=2*Settings!$B$12,Settings!$B$11,"NEITHER — under bench resolution"))))) | G30: =IF($B30="","",IF($F30=Settings!$B$6,MAX(2*Settings!$B$7,Settings!$B$4*$E30),IF($F30=Settings!$B$11,MAX(2*Settings!$B$12,Settings!$B$4*$E30),""))) | H30: =IF($B30="","",IF(LEFT($F30,7)="NEITHER","Cannot be weighed — split it, premix it, or raise the batch size",IF($G30>Settings!$B$4*$E30+0.0001,"Held to the scale's resolution, not "&TEXT(Settings!$B$4,"0%"),"")))
A31: =IF($B31="","",24) | D31: =IF($B31="","",$C31/1000) | E31: =IF($B31="","",$D31*$C$4) | F31: =IF($B31="","",IF($E31<=0,"NEITHER — zero",IF($E31>=Settings!$B$19,Settings!$B$6,IF($E31>Settings!$B$14,"NEITHER — over bench capacity",IF($E31>=2*Settings!$B$12,Settings!$B$11,"NEITHER — under bench resolution"))))) | G31: =IF($B31="","",IF($F31=Settings!$B$6,MAX(2*Settings!$B$7,Settings!$B$4*$E31),IF($F31=Settings!$B$11,MAX(2*Settings!$B$12,Settings!$B$4*$E31),""))) | H31: =IF($B31="","",IF(LEFT($F31,7)="NEITHER","Cannot be weighed — split it, premix it, or raise the batch size",IF($G31>Settings!$B$4*$E31+0.0001,"Held to the scale's resolution, not "&TEXT(Settings!$B$4,"0%"),"")))
A32: =IF($B32="","",25) | D32: =IF($B32="","",$C32/1000) | E32: =IF($B32="","",$D32*$C$4) | F32: =IF($B32="","",IF($E32<=0,"NEITHER — zero",IF($E32>=Settings!$B$19,Settings!$B$6,IF($E32>Settings!$B$14,"NEITHER — over bench capacity",IF($E32>=2*Settings!$B$12,Settings!$B$11,"NEITHER — under bench resolution"))))) | G32: =IF($B32="","",IF($F32=Settings!$B$6,MAX(2*Settings!$B$7,Settings!$B$4*$E32),IF($F32=Settings!$B$11,MAX(2*Settings!$B$12,Settings!$B$4*$E32),""))) | H32: =IF($B32="","",IF(LEFT($F32,7)="NEITHER","Cannot be weighed — split it, premix it, or raise the batch size",IF($G32>Settings!$B$4*$E32+0.0001,"Held to the scale's resolution, not "&TEXT(Settings!$B$4,"0%"),"")))
A33: =IF($B33="","",26) | D33: =IF($B33="","",$C33/1000) | E33: =IF($B33="","",$D33*$C$4) | F33: =IF($B33="","",IF($E33<=0,"NEITHER — zero",IF($E33>=Settings!$B$19,Settings!$B$6,IF($E33>Settings!$B$14,"NEITHER — over bench capacity",IF($E33>=2*Settings!$B$12,Settings!$B$11,"NEITHER — under bench resolution"))))) | G33: =IF($B33="","",IF($F33=Settings!$B$6,MAX(2*Settings!$B$7,Settings!$B$4*$E33),IF($F33=Settings!$B$11,MAX(2*Settings!$B$12,Settings!$B$4*$E33),""))) | H33: =IF($B33="","",IF(LEFT($F33,7)="NEITHER","Cannot be weighed — split it, premix it, or raise the batch size",IF($G33>Settings!$B$4*$E33+0.0001,"Held to the scale's resolution, not "&TEXT(Settings!$B$4,"0%"),"")))
A34: =IF($B34="","",27) | D34: =IF($B34="","",$C34/1000) | E34: =IF($B34="","",$D34*$C$4) | F34: =IF($B34="","",IF($E34<=0,"NEITHER — zero",IF($E34>=Settings!$B$19,Settings!$B$6,IF($E34>Settings!$B$14,"NEITHER — over bench capacity",IF($E34>=2*Settings!$B$12,Settings!$B$11,"NEITHER — under bench resolution"))))) | G34: =IF($B34="","",IF($F34=Settings!$B$6,MAX(2*Settings!$B$7,Settings!$B$4*$E34),IF($F34=Settings!$B$11,MAX(2*Settings!$B$12,Settings!$B$4*$E34),""))) | H34: =IF($B34="","",IF(LEFT($F34,7)="NEITHER","Cannot be weighed — split it, premix it, or raise the batch size",IF($G34>Settings!$B$4*$E34+0.0001,"Held to the scale's resolution, not "&TEXT(Settings!$B$4,"0%"),"")))
A35: =IF($B35="","",28) | D35: =IF($B35="","",$C35/1000) | E35: =IF($B35="","",$D35*$C$4) | F35: =IF($B35="","",IF($E35<=0,"NEITHER — zero",IF($E35>=Settings!$B$19,Settings!$B$6,IF($E35>Settings!$B$14,"NEITHER — over bench capacity",IF($E35>=2*Settings!$B$12,Settings!$B$11,"NEITHER — under bench resolution"))))) | G35: =IF($B35="","",IF($F35=Settings!$B$6,MAX(2*Settings!$B$7,Settings!$B$4*$E35),IF($F35=Settings!$B$11,MAX(2*Settings!$B$12,Settings!$B$4*$E35),""))) | H35: =IF($B35="","",IF(LEFT($F35,7)="NEITHER","Cannot be weighed — split it, premix it, or raise the batch size",IF($G35>Settings!$B$4*$E35+0.0001,"Held to the scale's resolution, not "&TEXT(Settings!$B$4,"0%"),"")))
A36: =IF($B36="","",29) | D36: =IF($B36="","",$C36/1000) | E36: =IF($B36="","",$D36*$C$4) | F36: =IF($B36="","",IF($E36<=0,"NEITHER — zero",IF($E36>=Settings!$B$19,Settings!$B$6,IF($E36>Settings!$B$14,"NEITHER — over bench capacity",IF($E36>=2*Settings!$B$12,Settings!$B$11,"NEITHER — under bench resolution"))))) | G36: =IF($B36="","",IF($F36=Settings!$B$6,MAX(2*Settings!$B$7,Settings!$B$4*$E36),IF($F36=Settings!$B$11,MAX(2*Settings!$B$12,Settings!$B$4*$E36),""))) | H36: =IF($B36="","",IF(LEFT($F36,7)="NEITHER","Cannot be weighed — split it, premix it, or raise the batch size",IF($G36>Settings!$B$4*$E36+0.0001,"Held to the scale's resolution, not "&TEXT(Settings!$B$4,"0%"),"")))
A37: =IF($B37="","",30) | D37: =IF($B37="","",$C37/1000) | E37: =IF($B37="","",$D37*$C$4) | F37: =IF($B37="","",IF($E37<=0,"NEITHER — zero",IF($E37>=Settings!$B$19,Settings!$B$6,IF($E37>Settings!$B$14,"NEITHER — over bench capacity",IF($E37>=2*Settings!$B$12,Settings!$B$11,"NEITHER — under bench resolution"))))) | G37: =IF($B37="","",IF($F37=Settings!$B$6,MAX(2*Settings!$B$7,Settings!$B$4*$E37),IF($F37=Settings!$B$11,MAX(2*Settings!$B$12,Settings!$B$4*$E37),""))) | H37: =IF($B37="","",IF(LEFT($F37,7)="NEITHER","Cannot be weighed — split it, premix it, or raise the batch size",IF($G37>Settings!$B$4*$E37+0.0001,"Held to the scale's resolution, not "&TEXT(Settings!$B$4,"0%"),"")))
A38: =IF($B38="","",31) | D38: =IF($B38="","",$C38/1000) | E38: =IF($B38="","",$D38*$C$4) | F38: =IF($B38="","",IF($E38<=0,"NEITHER — zero",IF($E38>=Settings!$B$19,Settings!$B$6,IF($E38>Settings!$B$14,"NEITHER — over bench capacity",IF($E38>=2*Settings!$B$12,Settings!$B$11,"NEITHER — under bench resolution"))))) | G38: =IF($B38="","",IF($F38=Settings!$B$6,MAX(2*Settings!$B$7,Settings!$B$4*$E38),IF($F38=Settings!$B$11,MAX(2*Settings!$B$12,Settings!$B$4*$E38),""))) | H38: =IF($B38="","",IF(LEFT($F38,7)="NEITHER","Cannot be weighed — split it, premix it, or raise the batch size",IF($G38>Settings!$B$4*$E38+0.0001,"Held to the scale's resolution, not "&TEXT(Settings!$B$4,"0%"),"")))
A39: =IF($B39="","",32) | D39: =IF($B39="","",$C39/1000) | E39: =IF($B39="","",$D39*$C$4) | F39: =IF($B39="","",IF($E39<=0,"NEITHER — zero",IF($E39>=Settings!$B$19,Settings!$B$6,IF($E39>Settings!$B$14,"NEITHER — over bench capacity",IF($E39>=2*Settings!$B$12,Settings!$B$11,"NEITHER — under bench resolution"))))) | G39: =IF($B39="","",IF($F39=Settings!$B$6,MAX(2*Settings!$B$7,Settings!$B$4*$E39),IF($F39=Settings!$B$11,MAX(2*Settings!$B$12,Settings!$B$4*$E39),""))) | H39: =IF($B39="","",IF(LEFT($F39,7)="NEITHER","Cannot be weighed — split it, premix it, or raise the batch size",IF($G39>Settings!$B$4*$E39+0.0001,"Held to the scale's resolution, not "&TEXT(Settings!$B$4,"0%"),"")))
A40: =IF($B40="","",33) | D40: =IF($B40="","",$C40/1000) | E40: =IF($B40="","",$D40*$C$4) | F40: =IF($B40="","",IF($E40<=0,"NEITHER — zero",IF($E40>=Settings!$B$19,Settings!$B$6,IF($E40>Settings!$B$14,"NEITHER — over bench capacity",IF($E40>=2*Settings!$B$12,Settings!$B$11,"NEITHER — under bench resolution"))))) | G40: =IF($B40="","",IF($F40=Settings!$B$6,MAX(2*Settings!$B$7,Settings!$B$4*$E40),IF($F40=Settings!$B$11,MAX(2*Settings!$B$12,Settings!$B$4*$E40),""))) | H40: =IF($B40="","",IF(LEFT($F40,7)="NEITHER","Cannot be weighed — split it, premix it, or raise the batch size",IF($G40>Settings!$B$4*$E40+0.0001,"Held to the scale's resolution, not "&TEXT(Settings!$B$4,"0%"),"")))
A41: =IF($B41="","",34) | D41: =IF($B41="","",$C41/1000) | E41: =IF($B41="","",$D41*$C$4) | F41: =IF($B41="","",IF($E41<=0,"NEITHER — zero",IF($E41>=Settings!$B$19,Settings!$B$6,IF($E41>Settings!$B$14,"NEITHER — over bench capacity",IF($E41>=2*Settings!$B$12,Settings!$B$11,"NEITHER — under bench resolution"))))) | G41: =IF($B41="","",IF($F41=Settings!$B$6,MAX(2*Settings!$B$7,Settings!$B$4*$E41),IF($F41=Settings!$B$11,MAX(2*Settings!$B$12,Settings!$B$4*$E41),""))) | H41: =IF($B41="","",IF(LEFT($F41,7)="NEITHER","Cannot be weighed — split it, premix it, or raise the batch size",IF($G41>Settings!$B$4*$E41+0.0001,"Held to the scale's resolution, not "&TEXT(Settings!$B$4,"0%"),"")))
...

Sheet Gochujang
A1: Gochujang
A2: Type in the shaded cells only. Weights are GRAMS PER 1 KG OF MEAT. Everything to the right is calculated.
A4: Batch base weight (g) | C4: 3200 | D4: A typical batch. Only the Target / Weigh-on / Tolerance columns use it — the station recomputes them from the meat it actually weighs.
A5: Product ID | C5: gochujang | D5: Bases this applies to | F5: chicken, pork, beef, mutton, fish
A6: Flour ingredient | C6: Binder (starch) | D6: Water ingredient | F6: Ice water
A7: # | B7: Ingredient | C7: g per 1 kg meat | D7: % of meat | E7: Target in this batch | F7: Weigh on | G7: Tolerance ± | H7: Note
A8: =IF($B8="","",1) -> 1 | B8: Salt | C8: 7.5 | D8: =IF($B8="","",$C8/1000) -> 0.0075 | E8: =IF($B8="","",$D8*$C$4) -> 24 | F8: =IF($B8="","",IF($E8<=0,"NEITHER — zero",IF($E8>=Settings!$B$19,Settings!$B$6,IF($E8>Settings!$B$14,"NEITHER — over bench capacity",IF($E8>=2*Settings!$B$12,Settings!$B$11,"NEITHER — under bench resolution"))))) -> Bench scale | G8: =IF($B8="","",IF($F8=Settings!$B$6,MAX(2*Settings!$B$7,Settings!$B$4*$E8),IF($F8=Settings!$B$11,MAX(2*Settings!$B$12,Settings!$B$4*$E8),""))) -> 0.48 | H8: =IF($B8="","",IF(LEFT($F8,7)="NEITHER","Cannot be weighed — split it, premix it, or raise the batch size",IF($G8>Settings!$B$4*$E8+0.0001,"Held to the scale's resolution, not "&TEXT(Settings!$B$4,"0%"),"")))
A9: =IF($B9="","",2) | D9: =IF($B9="","",$C9/1000) | E9: =IF($B9="","",$D9*$C$4) | F9: =IF($B9="","",IF($E9<=0,"NEITHER — zero",IF($E9>=Settings!$B$19,Settings!$B$6,IF($E9>Settings!$B$14,"NEITHER — over bench capacity",IF($E9>=2*Settings!$B$12,Settings!$B$11,"NEITHER — under bench resolution"))))) | G9: =IF($B9="","",IF($F9=Settings!$B$6,MAX(2*Settings!$B$7,Settings!$B$4*$E9),IF($F9=Settings!$B$11,MAX(2*Settings!$B$12,Settings!$B$4*$E9),""))) | H9: =IF($B9="","",IF(LEFT($F9,7)="NEITHER","Cannot be weighed — split it, premix it, or raise the batch size",IF($G9>Settings!$B$4*$E9+0.0001,"Held to the scale's resolution, not "&TEXT(Settings!$B$4,"0%"),"")))
A10: =IF($B10="","",3) | D10: =IF($B10="","",$C10/1000) | E10: =IF($B10="","",$D10*$C$4) | F10: =IF($B10="","",IF($E10<=0,"NEITHER — zero",IF($E10>=Settings!$B$19,Settings!$B$6,IF($E10>Settings!$B$14,"NEITHER — over bench capacity",IF($E10>=2*Settings!$B$12,Settings!$B$11,"NEITHER — under bench resolution"))))) | G10: =IF($B10="","",IF($F10=Settings!$B$6,MAX(2*Settings!$B$7,Settings!$B$4*$E10),IF($F10=Settings!$B$11,MAX(2*Settings!$B$12,Settings!$B$4*$E10),""))) | H10: =IF($B10="","",IF(LEFT($F10,7)="NEITHER","Cannot be weighed — split it, premix it, or raise the batch size",IF($G10>Settings!$B$4*$E10+0.0001,"Held to the scale's resolution, not "&TEXT(Settings!$B$4,"0%"),"")))
A11: =IF($B11="","",4) | D11: =IF($B11="","",$C11/1000) | E11: =IF($B11="","",$D11*$C$4) | F11: =IF($B11="","",IF($E11<=0,"NEITHER — zero",IF($E11>=Settings!$B$19,Settings!$B$6,IF($E11>Settings!$B$14,"NEITHER — over bench capacity",IF($E11>=2*Settings!$B$12,Settings!$B$11,"NEITHER — under bench resolution"))))) | G11: =IF($B11="","",IF($F11=Settings!$B$6,MAX(2*Settings!$B$7,Settings!$B$4*$E11),IF($F11=Settings!$B$11,MAX(2*Settings!$B$12,Settings!$B$4*$E11),""))) | H11: =IF($B11="","",IF(LEFT($F11,7)="NEITHER","Cannot be weighed — split it, premix it, or raise the batch size",IF($G11>Settings!$B$4*$E11+0.0001,"Held to the scale's resolution, not "&TEXT(Settings!$B$4,"0%"),"")))
A12: =IF($B12="","",5) | D12: =IF($B12="","",$C12/1000) | E12: =IF($B12="","",$D12*$C$4) | F12: =IF($B12="","",IF($E12<=0,"NEITHER — zero",IF($E12>=Settings!$B$19,Settings!$B$6,IF($E12>Settings!$B$14,"NEITHER — over bench capacity",IF($E12>=2*Settings!$B$12,Settings!$B$11,"NEITHER — under bench resolution"))))) | G12: =IF($B12="","",IF($F12=Settings!$B$6,MAX(2*Settings!$B$7,Settings!$B$4*$E12),IF($F12=Settings!$B$11,MAX(2*Settings!$B$12,Settings!$B$4*$E12),""))) | H12: =IF($B12="","",IF(LEFT($F12,7)="NEITHER","Cannot be weighed — split it, premix it, or raise the batch size",IF($G12>Settings!$B$4*$E12+0.0001,"Held to the scale's resolution, not "&TEXT(Settings!$B$4,"0%"),"")))
A13: =IF($B13="","",6) | D13: =IF($B13="","",$C13/1000) | E13: =IF($B13="","",$D13*$C$4) | F13: =IF($B13="","",IF($E13<=0,"NEITHER — zero",IF($E13>=Settings!$B$19,Settings!$B$6,IF($E13>Settings!$B$14,"NEITHER — over bench capacity",IF($E13>=2*Settings!$B$12,Settings!$B$11,"NEITHER — under bench resolution"))))) | G13: =IF($B13="","",IF($F13=Settings!$B$6,MAX(2*Settings!$B$7,Settings!$B$4*$E13),IF($F13=Settings!$B$11,MAX(2*Settings!$B$12,Settings!$B$4*$E13),""))) | H13: =IF($B13="","",IF(LEFT($F13,7)="NEITHER","Cannot be weighed — split it, premix it, or raise the batch size",IF($G13>Settings!$B$4*$E13+0.0001,"Held to the scale's resolution, not "&TEXT(Settings!$B$4,"0%"),"")))
A14: =IF($B14="","",7) | D14: =IF($B14="","",$C14/1000) | E14: =IF($B14="","",$D14*$C$4) | F14: =IF($B14="","",IF($E14<=0,"NEITHER — zero",IF($E14>=Settings!$B$19,Settings!$B$6,IF($E14>Settings!$B$14,"NEITHER — over bench capacity",IF($E14>=2*Settings!$B$12,Settings!$B$11,"NEITHER — under bench resolution"))))) | G14: =IF($B14="","",IF($F14=Settings!$B$6,MAX(2*Settings!$B$7,Settings!$B$4*$E14),IF($F14=Settings!$B$11,MAX(2*Settings!$B$12,Settings!$B$4*$E14),""))) | H14: =IF($B14="","",IF(LEFT($F14,7)="NEITHER","Cannot be weighed — split it, premix it, or raise the batch size",IF($G14>Settings!$B$4*$E14+0.0001,"Held to the scale's resolution, not "&TEXT(Settings!$B$4,"0%"),"")))
A15: =IF($B15="","",8) | D15: =IF($B15="","",$C15/1000) | E15: =IF($B15="","",$D15*$C$4) | F15: =IF($B15="","",IF($E15<=0,"NEITHER — zero",IF($E15>=Settings!$B$19,Settings!$B$6,IF($E15>Settings!$B$14,"NEITHER — over bench capacity",IF($E15>=2*Settings!$B$12,Settings!$B$11,"NEITHER — under bench resolution"))))) | G15: =IF($B15="","",IF($F15=Settings!$B$6,MAX(2*Settings!$B$7,Settings!$B$4*$E15),IF($F15=Settings!$B$11,MAX(2*Settings!$B$12,Settings!$B$4*$E15),""))) | H15: =IF($B15="","",IF(LEFT($F15,7)="NEITHER","Cannot be weighed — split it, premix it, or raise the batch size",IF($G15>Settings!$B$4*$E15+0.0001,"Held to the scale's resolution, not "&TEXT(Settings!$B$4,"0%"),"")))
A16: =IF($B16="","",9) | D16: =IF($B16="","",$C16/1000) | E16: =IF($B16="","",$D16*$C$4) | F16: =IF($B16="","",IF($E16<=0,"NEITHER — zero",IF($E16>=Settings!$B$19,Settings!$B$6,IF($E16>Settings!$B$14,"NEITHER — over bench capacity",IF($E16>=2*Settings!$B$12,Settings!$B$11,"NEITHER — under bench resolution"))))) | G16: =IF($B16="","",IF($F16=Settings!$B$6,MAX(2*Settings!$B$7,Settings!$B$4*$E16),IF($F16=Settings!$B$11,MAX(2*Settings!$B$12,Settings!$B$4*$E16),""))) | H16: =IF($B16="","",IF(LEFT($F16,7)="NEITHER","Cannot be weighed — split it, premix it, or raise the batch size",IF($G16>Settings!$B$4*$E16+0.0001,"Held to the scale's resolution, not "&TEXT(Settings!$B$4,"0%"),"")))
A17: =IF($B17="","",10) | D17: =IF($B17="","",$C17/1000) | E17: =IF($B17="","",$D17*$C$4) | F17: =IF($B17="","",IF($E17<=0,"NEITHER — zero",IF($E17>=Settings!$B$19,Settings!$B$6,IF($E17>Settings!$B$14,"NEITHER — over bench capacity",IF($E17>=2*Settings!$B$12,Settings!$B$11,"NEITHER — under bench resolution"))))) | G17: =IF($B17="","",IF($F17=Settings!$B$6,MAX(2*Settings!$B$7,Settings!$B$4*$E17),IF($F17=Settings!$B$11,MAX(2*Settings!$B$12,Settings!$B$4*$E17),""))) | H17: =IF($B17="","",IF(LEFT($F17,7)="NEITHER","Cannot be weighed — split it, premix it, or raise the batch size",IF($G17>Settings!$B$4*$E17+0.0001,"Held to the scale's resolution, not "&TEXT(Settings!$B$4,"0%"),"")))
A18: =IF($B18="","",11) | D18: =IF($B18="","",$C18/1000) | E18: =IF($B18="","",$D18*$C$4) | F18: =IF($B18="","",IF($E18<=0,"NEITHER — zero",IF($E18>=Settings!$B$19,Settings!$B$6,IF($E18>Settings!$B$14,"NEITHER — over bench capacity",IF($E18>=2*Settings!$B$12,Settings!$B$11,"NEITHER — under bench resolution"))))) | G18: =IF($B18="","",IF($F18=Settings!$B$6,MAX(2*Settings!$B$7,Settings!$B$4*$E18),IF($F18=Settings!$B$11,MAX(2*Settings!$B$12,Settings!$B$4*$E18),""))) | H18: =IF($B18="","",IF(LEFT($F18,7)="NEITHER","Cannot be weighed — split it, premix it, or raise the batch size",IF($G18>Settings!$B$4*$E18+0.0001,"Held to the scale's resolution, not "&TEXT(Settings!$B$4,"0%"),"")))
A19: =IF($B19="","",12) | D19: =IF($B19="","",$C19/1000) | E19: =IF($B19="","",$D19*$C$4) | F19: =IF($B19="","",IF($E19<=0,"NEITHER — zero",IF($E19>=Settings!$B$19,Settings!$B$6,IF($E19>Settings!$B$14,"NEITHER — over bench capacity",IF($E19>=2*Settings!$B$12,Settings!$B$11,"NEITHER — under bench resolution"))))) | G19: =IF($B19="","",IF($F19=Settings!$B$6,MAX(2*Settings!$B$7,Settings!$B$4*$E19),IF($F19=Settings!$B$11,MAX(2*Settings!$B$12,Settings!$B$4*$E19),""))) | H19: =IF($B19="","",IF(LEFT($F19,7)="NEITHER","Cannot be weighed — split it, premix it, or raise the batch size",IF($G19>Settings!$B$4*$E19+0.0001,"Held to the scale's resolution, not "&TEXT(Settings!$B$4,"0%"),"")))
A20: =IF($B20="","",13) | D20: =IF($B20="","",$C20/1000) | E20: =IF($B20="","",$D20*$C$4) | F20: =IF($B20="","",IF($E20<=0,"NEITHER — zero",IF($E20>=Settings!$B$19,Settings!$B$6,IF($E20>Settings!$B$14,"NEITHER — over bench capacity",IF($E20>=2*Settings!$B$12,Settings!$B$11,"NEITHER — under bench resolution"))))) | G20: =IF($B20="","",IF($F20=Settings!$B$6,MAX(2*Settings!$B$7,Settings!$B$4*$E20),IF($F20=Settings!$B$11,MAX(2*Settings!$B$12,Settings!$B$4*$E20),""))) | H20: =IF($B20="","",IF(LEFT($F20,7)="NEITHER","Cannot be weighed — split it, premix it, or raise the batch size",IF($G20>Settings!$B$4*$E20+0.0001,"Held to the scale's resolution, not "&TEXT(Settings!$B$4,"0%"),"")))
A21: =IF($B21="","",14) | D21: =IF($B21="","",$C21/1000) | E21: =IF($B21="","",$D21*$C$4) | F21: =IF($B21="","",IF($E21<=0,"NEITHER — zero",IF($E21>=Settings!$B$19,Settings!$B$6,IF($E21>Settings!$B$14,"NEITHER — over bench capacity",IF($E21>=2*Settings!$B$12,Settings!$B$11,"NEITHER — under bench resolution"))))) | G21: =IF($B21="","",IF($F21=Settings!$B$6,MAX(2*Settings!$B$7,Settings!$B$4*$E21),IF($F21=Settings!$B$11,MAX(2*Settings!$B$12,Settings!$B$4*$E21),""))) | H21: =IF($B21="","",IF(LEFT($F21,7)="NEITHER","Cannot be weighed — split it, premix it, or raise the batch size",IF($G21>Settings!$B$4*$E21+0.0001,"Held to the scale's resolution, not "&TEXT(Settings!$B$4,"0%"),"")))
A22: =IF($B22="","",15) | D22: =IF($B22="","",$C22/1000) | E22: =IF($B22="","",$D22*$C$4) | F22: =IF($B22="","",IF($E22<=0,"NEITHER — zero",IF($E22>=Settings!$B$19,Settings!$B$6,IF($E22>Settings!$B$14,"NEITHER — over bench capacity",IF($E22>=2*Settings!$B$12,Settings!$B$11,"NEITHER — under bench resolution"))))) | G22: =IF($B22="","",IF($F22=Settings!$B$6,MAX(2*Settings!$B$7,Settings!$B$4*$E22),IF($F22=Settings!$B$11,MAX(2*Settings!$B$12,Settings!$B$4*$E22),""))) | H22: =IF($B22="","",IF(LEFT($F22,7)="NEITHER","Cannot be weighed — split it, premix it, or raise the batch size",IF($G22>Settings!$B$4*$E22+0.0001,"Held to the scale's resolution, not "&TEXT(Settings!$B$4,"0%"),"")))
A23: =IF($B23="","",16) | D23: =IF($B23="","",$C23/1000) | E23: =IF($B23="","",$D23*$C$4) | F23: =IF($B23="","",IF($E23<=0,"NEITHER — zero",IF($E23>=Settings!$B$19,Settings!$B$6,IF($E23>Settings!$B$14,"NEITHER — over bench capacity",IF($E23>=2*Settings!$B$12,Settings!$B$11,"NEITHER — under bench resolution"))))) | G23: =IF($B23="","",IF($F23=Settings!$B$6,MAX(2*Settings!$B$7,Settings!$B$4*$E23),IF($F23=Settings!$B$11,MAX(2*Settings!$B$12,Settings!$B$4*$E23),""))) | H23: =IF($B23="","",IF(LEFT($F23,7)="NEITHER","Cannot be weighed — split it, premix it, or raise the batch size",IF($G23>Settings!$B$4*$E23+0.0001,"Held to the scale's resolution, not "&TEXT(Settings!$B$4,"0%"),"")))
A24: =IF($B24="","",17) | D24: =IF($B24="","",$C24/1000) | E24: =IF($B24="","",$D24*$C$4) | F24: =IF($B24="","",IF($E24<=0,"NEITHER — zero",IF($E24>=Settings!$B$19,Settings!$B$6,IF($E24>Settings!$B$14,"NEITHER — over bench capacity",IF($E24>=2*Settings!$B$12,Settings!$B$11,"NEITHER — under bench resolution"))))) | G24: =IF($B24="","",IF($F24=Settings!$B$6,MAX(2*Settings!$B$7,Settings!$B$4*$E24),IF($F24=Settings!$B$11,MAX(2*Settings!$B$12,Settings!$B$4*$E24),""))) | H24: =IF($B24="","",IF(LEFT($F24,7)="NEITHER","Cannot be weighed — split it, premix it, or raise the batch size",IF($G24>Settings!$B$4*$E24+0.0001,"Held to the scale's resolution, not "&TEXT(Settings!$B$4,"0%"),"")))
A25: =IF($B25="","",18) | D25: =IF($B25="","",$C25/1000) | E25: =IF($B25="","",$D25*$C$4) | F25: =IF($B25="","",IF($E25<=0,"NEITHER — zero",IF($E25>=Settings!$B$19,Settings!$B$6,IF($E25>Settings!$B$14,"NEITHER — over bench capacity",IF($E25>=2*Settings!$B$12,Settings!$B$11,"NEITHER — under bench resolution"))))) | G25: =IF($B25="","",IF($F25=Settings!$B$6,MAX(2*Settings!$B$7,Settings!$B$4*$E25),IF($F25=Settings!$B$11,MAX(2*Settings!$B$12,Settings!$B$4*$E25),""))) | H25: =IF($B25="","",IF(LEFT($F25,7)="NEITHER","Cannot be weighed — split it, premix it, or raise the batch size",IF($G25>Settings!$B$4*$E25+0.0001,"Held to the scale's resolution, not "&TEXT(Settings!$B$4,"0%"),"")))
A26: =IF($B26="","",19) | D26: =IF($B26="","",$C26/1000) | E26: =IF($B26="","",$D26*$C$4) | F26: =IF($B26="","",IF($E26<=0,"NEITHER — zero",IF($E26>=Settings!$B$19,Settings!$B$6,IF($E26>Settings!$B$14,"NEITHER — over bench capacity",IF($E26>=2*Settings!$B$12,Settings!$B$11,"NEITHER — under bench resolution"))))) | G26: =IF($B26="","",IF($F26=Settings!$B$6,MAX(2*Settings!$B$7,Settings!$B$4*$E26),IF($F26=Settings!$B$11,MAX(2*Settings!$B$12,Settings!$B$4*$E26),""))) | H26: =IF($B26="","",IF(LEFT($F26,7)="NEITHER","Cannot be weighed — split it, premix it, or raise the batch size",IF($G26>Settings!$B$4*$E26+0.0001,"Held to the scale's resolution, not "&TEXT(Settings!$B$4,"0%"),"")))
A27: =IF($B27="","",20) | D27: =IF($B27="","",$C27/1000) | E27: =IF($B27="","",$D27*$C$4) | F27: =IF($B27="","",IF($E27<=0,"NEITHER — zero",IF($E27>=Settings!$B$19,Settings!$B$6,IF($E27>Settings!$B$14,"NEITHER — over bench capacity",IF($E27>=2*Settings!$B$12,Settings!$B$11,"NEITHER — under bench resolution"))))) | G27: =IF($B27="","",IF($F27=Settings!$B$6,MAX(2*Settings!$B$7,Settings!$B$4*$E27),IF($F27=Settings!$B$11,MAX(2*Settings!$B$12,Settings!$B$4*$E27),""))) | H27: =IF($B27="","",IF(LEFT($F27,7)="NEITHER","Cannot be weighed — split it, premix it, or raise the batch size",IF($G27>Settings!$B$4*$E27+0.0001,"Held to the scale's resolution, not "&TEXT(Settings!$B$4,"0%"),"")))
A28: =IF($B28="","",21) | D28: =IF($B28="","",$C28/1000) | E28: =IF($B28="","",$D28*$C$4) | F28: =IF($B28="","",IF($E28<=0,"NEITHER — zero",IF($E28>=Settings!$B$19,Settings!$B$6,IF($E28>Settings!$B$14,"NEITHER — over bench capacity",IF($E28>=2*Settings!$B$12,Settings!$B$11,"NEITHER — under bench resolution"))))) | G28: =IF($B28="","",IF($F28=Settings!$B$6,MAX(2*Settings!$B$7,Settings!$B$4*$E28),IF($F28=Settings!$B$11,MAX(2*Settings!$B$12,Settings!$B$4*$E28),""))) | H28: =IF($B28="","",IF(LEFT($F28,7)="NEITHER","Cannot be weighed — split it, premix it, or raise the batch size",IF($G28>Settings!$B$4*$E28+0.0001,"Held to the scale's resolution, not "&TEXT(Settings!$B$4,"0%"),"")))
A29: =IF($B29="","",22) | D29: =IF($B29="","",$C29/1000) | E29: =IF($B29="","",$D29*$C$4) | F29: =IF($B29="","",IF($E29<=0,"NEITHER — zero",IF($E29>=Settings!$B$19,Settings!$B$6,IF($E29>Settings!$B$14,"NEITHER — over bench capacity",IF($E29>=2*Settings!$B$12,Settings!$B$11,"NEITHER — under bench resolution"))))) | G29: =IF($B29="","",IF($F29=Settings!$B$6,MAX(2*Settings!$B$7,Settings!$B$4*$E29),IF($F29=Settings!$B$11,MAX(2*Settings!$B$12,Settings!$B$4*$E29),""))) | H29: =IF($B29="","",IF(LEFT($F29,7)="NEITHER","Cannot be weighed — split it, premix it, or raise the batch size",IF($G29>Settings!$B$4*$E29+0.0001,"Held to the scale's resolution, not "&TEXT(Settings!$B$4,"0%"),"")))
A30: =IF($B30="","",23) | D30: =IF($B30="","",$C30/1000) | E30: =IF($B30="","",$D30*$C$4) | F30: =IF($B30="","",IF($E30<=0,"NEITHER — zero",IF($E30>=Settings!$B$19,Settings!$B$6,IF($E30>Settings!$B$14,"NEITHER — over bench capacity",IF($E30>=2*Settings!$B$12,Settings!$B$11,"NEITHER — under bench resolution"))))) | G30: =IF($B30="","",IF($F30=Settings!$B$6,MAX(2*Settings!$B$7,Settings!$B$4*$E30),IF($F30=Settings!$B$11,MAX(2*Settings!$B$12,Settings!$B$4*$E30),""))) | H30: =IF($B30="","",IF(LEFT($F30,7)="NEITHER","Cannot be weighed — split it, premix it, or raise the batch size",IF($G30>Settings!$B$4*$E30+0.0001,"Held to the scale's resolution, not "&TEXT(Settings!$B$4,"0%"),"")))
A31: =IF($B31="","",24) | D31: =IF($B31="","",$C31/1000) | E31: =IF($B31="","",$D31*$C$4) | F31: =IF($B31="","",IF($E31<=0,"NEITHER — zero",IF($E31>=Settings!$B$19,Settings!$B$6,IF($E31>Settings!$B$14,"NEITHER — over bench capacity",IF($E31>=2*Settings!$B$12,Settings!$B$11,"NEITHER — under bench resolution"))))) | G31: =IF($B31="","",IF($F31=Settings!$B$6,MAX(2*Settings!$B$7,Settings!$B$4*$E31),IF($F31=Settings!$B$11,MAX(2*Settings!$B$12,Settings!$B$4*$E31),""))) | H31: =IF($B31="","",IF(LEFT($F31,7)="NEITHER","Cannot be weighed — split it, premix it, or raise the batch size",IF($G31>Settings!$B$4*$E31+0.0001,"Held to the scale's resolution, not "&TEXT(Settings!$B$4,"0%"),"")))
A32: =IF($B32="","",25) | D32: =IF($B32="","",$C32/1000) | E32: =IF($B32="","",$D32*$C$4) | F32: =IF($B32="","",IF($E32<=0,"NEITHER — zero",IF($E32>=Settings!$B$19,Settings!$B$6,IF($E32>Settings!$B$14,"NEITHER — over bench capacity",IF($E32>=2*Settings!$B$12,Settings!$B$11,"NEITHER — under bench resolution"))))) | G32: =IF($B32="","",IF($F32=Settings!$B$6,MAX(2*Settings!$B$7,Settings!$B$4*$E32),IF($F32=Settings!$B$11,MAX(2*Settings!$B$12,Settings!$B$4*$E32),""))) | H32: =IF($B32="","",IF(LEFT($F32,7)="NEITHER","Cannot be weighed — split it, premix it, or raise the batch size",IF($G32>Settings!$B$4*$E32+0.0001,"Held to the scale's resolution, not "&TEXT(Settings!$B$4,"0%"),"")))
A33: =IF($B33="","",26) | D33: =IF($B33="","",$C33/1000) | E33: =IF($B33="","",$D33*$C$4) | F33: =IF($B33="","",IF($E33<=0,"NEITHER — zero",IF($E33>=Settings!$B$19,Settings!$B$6,IF($E33>Settings!$B$14,"NEITHER — over bench capacity",IF($E33>=2*Settings!$B$12,Settings!$B$11,"NEITHER — under bench resolution"))))) | G33: =IF($B33="","",IF($F33=Settings!$B$6,MAX(2*Settings!$B$7,Settings!$B$4*$E33),IF($F33=Settings!$B$11,MAX(2*Settings!$B$12,Settings!$B$4*$E33),""))) | H33: =IF($B33="","",IF(LEFT($F33,7)="NEITHER","Cannot be weighed — split it, premix it, or raise the batch size",IF($G33>Settings!$B$4*$E33+0.0001,"Held to the scale's resolution, not "&TEXT(Settings!$B$4,"0%"),"")))
A34: =IF($B34="","",27) | D34: =IF($B34="","",$C34/1000) | E34: =IF($B34="","",$D34*$C$4) | F34: =IF($B34="","",IF($E34<=0,"NEITHER — zero",IF($E34>=Settings!$B$19,Settings!$B$6,IF($E34>Settings!$B$14,"NEITHER — over bench capacity",IF($E34>=2*Settings!$B$12,Settings!$B$11,"NEITHER — under bench resolution"))))) | G34: =IF($B34="","",IF($F34=Settings!$B$6,MAX(2*Settings!$B$7,Settings!$B$4*$E34),IF($F34=Settings!$B$11,MAX(2*Settings!$B$12,Settings!$B$4*$E34),""))) | H34: =IF($B34="","",IF(LEFT($F34,7)="NEITHER","Cannot be weighed — split it, premix it, or raise the batch size",IF($G34>Settings!$B$4*$E34+0.0001,"Held to the scale's resolution, not "&TEXT(Settings!$B$4,"0%"),"")))
A35: =IF($B35="","",28) | D35: =IF($B35="","",$C35/1000) | E35: =IF($B35="","",$D35*$C$4) | F35: =IF($B35="","",IF($E35<=0,"NEITHER — zero",IF($E35>=Settings!$B$19,Settings!$B$6,IF($E35>Settings!$B$14,"NEITHER — over bench capacity",IF($E35>=2*Settings!$B$12,Settings!$B$11,"NEITHER — under bench resolution"))))) | G35: =IF($B35="","",IF($F35=Settings!$B$6,MAX(2*Settings!$B$7,Settings!$B$4*$E35),IF($F35=Settings!$B$11,MAX(2*Settings!$B$12,Settings!$B$4*$E35),""))) | H35: =IF($B35="","",IF(LEFT($F35,7)="NEITHER","Cannot be weighed — split it, premix it, or raise the batch size",IF($G35>Settings!$B$4*$E35+0.0001,"Held to the scale's resolution, not "&TEXT(Settings!$B$4,"0%"),"")))
A36: =IF($B36="","",29) | D36: =IF($B36="","",$C36/1000) | E36: =IF($B36="","",$D36*$C$4) | F36: =IF($B36="","",IF($E36<=0,"NEITHER — zero",IF($E36>=Settings!$B$19,Settings!$B$6,IF($E36>Settings!$B$14,"NEITHER — over bench capacity",IF($E36>=2*Settings!$B$12,Settings!$B$11,"NEITHER — under bench resolution"))))) | G36: =IF($B36="","",IF($F36=Settings!$B$6,MAX(2*Settings!$B$7,Settings!$B$4*$E36),IF($F36=Settings!$B$11,MAX(2*Settings!$B$12,Settings!$B$4*$E36),""))) | H36: =IF($B36="","",IF(LEFT($F36,7)="NEITHER","Cannot be weighed — split it, premix it, or raise the batch size",IF($G36>Settings!$B$4*$E36+0.0001,"Held to the scale's resolution, not "&TEXT(Settings!$B$4,"0%"),"")))
A37: =IF($B37="","",30) | D37: =IF($B37="","",$C37/1000) | E37: =IF($B37="","",$D37*$C$4) | F37: =IF($B37="","",IF($E37<=0,"NEITHER — zero",IF($E37>=Settings!$B$19,Settings!$B$6,IF($E37>Settings!$B$14,"NEITHER — over bench capacity",IF($E37>=2*Settings!$B$12,Settings!$B$11,"NEITHER — under bench resolution"))))) | G37: =IF($B37="","",IF($F37=Settings!$B$6,MAX(2*Settings!$B$7,Settings!$B$4*$E37),IF($F37=Settings!$B$11,MAX(2*Settings!$B$12,Settings!$B$4*$E37),""))) | H37: =IF($B37="","",IF(LEFT($F37,7)="NEITHER","Cannot be weighed — split it, premix it, or raise the batch size",IF($G37>Settings!$B$4*$E37+0.0001,"Held to the scale's resolution, not "&TEXT(Settings!$B$4,"0%"),"")))
A38: =IF($B38="","",31) | D38: =IF($B38="","",$C38/1000) | E38: =IF($B38="","",$D38*$C$4) | F38: =IF($B38="","",IF($E38<=0,"NEITHER — zero",IF($E38>=Settings!$B$19,Settings!$B$6,IF($E38>Settings!$B$14,"NEITHER — over bench capacity",IF($E38>=2*Settings!$B$12,Settings!$B$11,"NEITHER — under bench resolution"))))) | G38: =IF($B38="","",IF($F38=Settings!$B$6,MAX(2*Settings!$B$7,Settings!$B$4*$E38),IF($F38=Settings!$B$11,MAX(2*Settings!$B$12,Settings!$B$4*$E38),""))) | H38: =IF($B38="","",IF(LEFT($F38,7)="NEITHER","Cannot be weighed — split it, premix it, or raise the batch size",IF($G38>Settings!$B$4*$E38+0.0001,"Held to the scale's resolution, not "&TEXT(Settings!$B$4,"0%"),"")))
A39: =IF($B39="","",32) | D39: =IF($B39="","",$C39/1000) | E39: =IF($B39="","",$D39*$C$4) | F39: =IF($B39="","",IF($E39<=0,"NEITHER — zero",IF($E39>=Settings!$B$19,Settings!$B$6,IF($E39>Settings!$B$14,"NEITHER — over bench capacity",IF($E39>=2*Settings!$B$12,Settings!$B$11,"NEITHER — under bench resolution"))))) | G39: =IF($B39="","",IF($F39=Settings!$B$6,MAX(2*Settings!$B$7,Settings!$B$4*$E39),IF($F39=Settings!$B$11,MAX(2*Settings!$B$12,Settings!$B$4*$E39),""))) | H39: =IF($B39="","",IF(LEFT($F39,7)="NEITHER","Cannot be weighed — split it, premix it, or raise the batch size",IF($G39>Settings!$B$4*$E39+0.0001,"Held to the scale's resolution, not "&TEXT(Settings!$B$4,"0%"),"")))
A40: =IF($B40="","",33) | D40: =IF($B40="","",$C40/1000) | E40: =IF($B40="","",$D40*$C$4) | F40: =IF($B40="","",IF($E40<=0,"NEITHER — zero",IF($E40>=Settings!$B$19,Settings!$B$6,IF($E40>Settings!$B$14,"NEITHER — over bench capacity",IF($E40>=2*Settings!$B$12,Settings!$B$11,"NEITHER — under bench resolution"))))) | G40: =IF($B40="","",IF($F40=Settings!$B$6,MAX(2*Settings!$B$7,Settings!$B$4*$E40),IF($F40=Settings!$B$11,MAX(2*Settings!$B$12,Settings!$B$4*$E40),""))) | H40: =IF($B40="","",IF(LEFT($F40,7)="NEITHER","Cannot be weighed — split it, premix it, or raise the batch size",IF($G40>Settings!$B$4*$E40+0.0001,"Held to the scale's resolution, not "&TEXT(Settings!$B$4,"0%"),"")))
A41: =IF($B41="","",34) | D41: =IF($B41="","",$C41/1000) | E41: =IF($B41="","",$D41*$C$4) | F41: =IF($B41="","",IF($E41<=0,"NEITHER — zero",IF($E41>=Settings!$B$19,Settings!$B$6,IF($E41>Settings!$B$14,"NEITHER — over bench capacity",IF($E41>=2*Settings!$B$12,Settings!$B$11,"NEITHER — under bench resolution"))))) | G41: =IF($B41="","",IF($F41=Settings!$B$6,MAX(2*Settings!$B$7,Settings!$B$4*$E41),IF($F41=Settings!$B$11,MAX(2*Settings!$B$12,Settings!$B$4*$E41),""))) | H41: =IF($B41="","",IF(LEFT($F41,7)="NEITHER","Cannot be weighed — split it, premix it, or raise the batch size",IF($G41>Settings!$B$4*$E41+0.0001,"Held to the scale's resolution, not "&TEXT(Settings!$B$4,"0%"),"")))
...

Sheet Pepper
A1: Pepper
A2: Type in the shaded cells only. Weights are GRAMS PER 1 KG OF MEAT. Everything to the right is calculated.
A4: Batch base weight (g) | C4: 3200 | D4: A typical batch. Only the Target / Weigh-on / Tolerance columns use it — the station recomputes them from the meat it actually weighs.
A5: Product ID | C5: pepper | D5: Bases this applies to | F5: chicken, pork, beef, mutton, fish
A6: Flour ingredient | C6: Binder (starch) | D6: Water ingredient | F6: Ice water
A7: # | B7: Ingredient | C7: g per 1 kg meat | D7: % of meat | E7: Target in this batch | F7: Weigh on | G7: Tolerance ± | H7: Note
A8: =IF($B8="","",1) -> 1 | B8: Salt | C8: 7.5 | D8: =IF($B8="","",$C8/1000) -> 0.0075 | E8: =IF($B8="","",$D8*$C$4) -> 24 | F8: =IF($B8="","",IF($E8<=0,"NEITHER — zero",IF($E8>=Settings!$B$19,Settings!$B$6,IF($E8>Settings!$B$14,"NEITHER — over bench capacity",IF($E8>=2*Settings!$B$12,Settings!$B$11,"NEITHER — under bench resolution"))))) -> Bench scale | G8: =IF($B8="","",IF($F8=Settings!$B$6,MAX(2*Settings!$B$7,Settings!$B$4*$E8),IF($F8=Settings!$B$11,MAX(2*Settings!$B$12,Settings!$B$4*$E8),""))) -> 0.48 | H8: =IF($B8="","",IF(LEFT($F8,7)="NEITHER","Cannot be weighed — split it, premix it, or raise the batch size",IF($G8>Settings!$B$4*$E8+0.0001,"Held to the scale's resolution, not "&TEXT(Settings!$B$4,"0%"),"")))
A9: =IF($B9="","",2) | D9: =IF($B9="","",$C9/1000) | E9: =IF($B9="","",$D9*$C$4) | F9: =IF($B9="","",IF($E9<=0,"NEITHER — zero",IF($E9>=Settings!$B$19,Settings!$B$6,IF($E9>Settings!$B$14,"NEITHER — over bench capacity",IF($E9>=2*Settings!$B$12,Settings!$B$11,"NEITHER — under bench resolution"))))) | G9: =IF($B9="","",IF($F9=Settings!$B$6,MAX(2*Settings!$B$7,Settings!$B$4*$E9),IF($F9=Settings!$B$11,MAX(2*Settings!$B$12,Settings!$B$4*$E9),""))) | H9: =IF($B9="","",IF(LEFT($F9,7)="NEITHER","Cannot be weighed — split it, premix it, or raise the batch size",IF($G9>Settings!$B$4*$E9+0.0001,"Held to the scale's resolution, not "&TEXT(Settings!$B$4,"0%"),"")))
A10: =IF($B10="","",3) | D10: =IF($B10="","",$C10/1000) | E10: =IF($B10="","",$D10*$C$4) | F10: =IF($B10="","",IF($E10<=0,"NEITHER — zero",IF($E10>=Settings!$B$19,Settings!$B$6,IF($E10>Settings!$B$14,"NEITHER — over bench capacity",IF($E10>=2*Settings!$B$12,Settings!$B$11,"NEITHER — under bench resolution"))))) | G10: =IF($B10="","",IF($F10=Settings!$B$6,MAX(2*Settings!$B$7,Settings!$B$4*$E10),IF($F10=Settings!$B$11,MAX(2*Settings!$B$12,Settings!$B$4*$E10),""))) | H10: =IF($B10="","",IF(LEFT($F10,7)="NEITHER","Cannot be weighed — split it, premix it, or raise the batch size",IF($G10>Settings!$B$4*$E10+0.0001,"Held to the scale's resolution, not "&TEXT(Settings!$B$4,"0%"),"")))
A11: =IF($B11="","",4) | D11: =IF($B11="","",$C11/1000) | E11: =IF($B11="","",$D11*$C$4) | F11: =IF($B11="","",IF($E11<=0,"NEITHER — zero",IF($E11>=Settings!$B$19,Settings!$B$6,IF($E11>Settings!$B$14,"NEITHER — over bench capacity",IF($E11>=2*Settings!$B$12,Settings!$B$11,"NEITHER — under bench resolution"))))) | G11: =IF($B11="","",IF($F11=Settings!$B$6,MAX(2*Settings!$B$7,Settings!$B$4*$E11),IF($F11=Settings!$B$11,MAX(2*Settings!$B$12,Settings!$B$4*$E11),""))) | H11: =IF($B11="","",IF(LEFT($F11,7)="NEITHER","Cannot be weighed — split it, premix it, or raise the batch size",IF($G11>Settings!$B$4*$E11+0.0001,"Held to the scale's resolution, not "&TEXT(Settings!$B$4,"0%"),"")))
A12: =IF($B12="","",5) | D12: =IF($B12="","",$C12/1000) | E12: =IF($B12="","",$D12*$C$4) | F12: =IF($B12="","",IF($E12<=0,"NEITHER — zero",IF($E12>=Settings!$B$19,Settings!$B$6,IF($E12>Settings!$B$14,"NEITHER — over bench capacity",IF($E12>=2*Settings!$B$12,Settings!$B$11,"NEITHER — under bench resolution"))))) | G12: =IF($B12="","",IF($F12=Settings!$B$6,MAX(2*Settings!$B$7,Settings!$B$4*$E12),IF($F12=Settings!$B$11,MAX(2*Settings!$B$12,Settings!$B$4*$E12),""))) | H12: =IF($B12="","",IF(LEFT($F12,7)="NEITHER","Cannot be weighed — split it, premix it, or raise the batch size",IF($G12>Settings!$B$4*$E12+0.0001,"Held to the scale's resolution, not "&TEXT(Settings!$B$4,"0%"),"")))
A13: =IF($B13="","",6) | D13: =IF($B13="","",$C13/1000) | E13: =IF($B13="","",$D13*$C$4) | F13: =IF($B13="","",IF($E13<=0,"NEITHER — zero",IF($E13>=Settings!$B$19,Settings!$B$6,IF($E13>Settings!$B$14,"NEITHER — over bench capacity",IF($E13>=2*Settings!$B$12,Settings!$B$11,"NEITHER — under bench resolution"))))) | G13: =IF($B13="","",IF($F13=Settings!$B$6,MAX(2*Settings!$B$7,Settings!$B$4*$E13),IF($F13=Settings!$B$11,MAX(2*Settings!$B$12,Settings!$B$4*$E13),""))) | H13: =IF($B13="","",IF(LEFT($F13,7)="NEITHER","Cannot be weighed — split it, premix it, or raise the batch size",IF($G13>Settings!$B$4*$E13+0.0001,"Held to the scale's resolution, not "&TEXT(Settings!$B$4,"0%"),"")))
A14: =IF($B14="","",7) | D14: =IF($B14="","",$C14/1000) | E14: =IF($B14="","",$D14*$C$4) | F14: =IF($B14="","",IF($E14<=0,"NEITHER — zero",IF($E14>=Settings!$B$19,Settings!$B$6,IF($E14>Settings!$B$14,"NEITHER — over bench capacity",IF($E14>=2*Settings!$B$12,Settings!$B$11,"NEITHER — under bench resolution"))))) | G14: =IF($B14="","",IF($F14=Settings!$B$6,MAX(2*Settings!$B$7,Settings!$B$4*$E14),IF($F14=Settings!$B$11,MAX(2*Settings!$B$12,Settings!$B$4*$E14),""))) | H14: =IF($B14="","",IF(LEFT($F14,7)="NEITHER","Cannot be weighed — split it, premix it, or raise the batch size",IF($G14>Settings!$B$4*$E14+0.0001,"Held to the scale's resolution, not "&TEXT(Settings!$B$4,"0%"),"")))
A15: =IF($B15="","",8) | D15: =IF($B15="","",$C15/1000) | E15: =IF($B15="","",$D15*$C$4) | F15: =IF($B15="","",IF($E15<=0,"NEITHER — zero",IF($E15>=Settings!$B$19,Settings!$B$6,IF($E15>Settings!$B$14,"NEITHER — over bench capacity",IF($E15>=2*Settings!$B$12,Settings!$B$11,"NEITHER — under bench resolution"))))) | G15: =IF($B15="","",IF($F15=Settings!$B$6,MAX(2*Settings!$B$7,Settings!$B$4*$E15),IF($F15=Settings!$B$11,MAX(2*Settings!$B$12,Settings!$B$4*$E15),""))) | H15: =IF($B15="","",IF(LEFT($F15,7)="NEITHER","Cannot be weighed — split it, premix it, or raise the batch size",IF($G15>Settings!$B$4*$E15+0.0001,"Held to the scale's resolution, not "&TEXT(Settings!$B$4,"0%"),"")))
A16: =IF($B16="","",9) | D16: =IF($B16="","",$C16/1000) | E16: =IF($B16="","",$D16*$C$4) | F16: =IF($B16="","",IF($E16<=0,"NEITHER — zero",IF($E16>=Settings!$B$19,Settings!$B$6,IF($E16>Settings!$B$14,"NEITHER — over bench capacity",IF($E16>=2*Settings!$B$12,Settings!$B$11,"NEITHER — under bench resolution"))))) | G16: =IF($B16="","",IF($F16=Settings!$B$6,MAX(2*Settings!$B$7,Settings!$B$4*$E16),IF($F16=Settings!$B$11,MAX(2*Settings!$B$12,Settings!$B$4*$E16),""))) | H16: =IF($B16="","",IF(LEFT($F16,7)="NEITHER","Cannot be weighed — split it, premix it, or raise the batch size",IF($G16>Settings!$B$4*$E16+0.0001,"Held to the scale's resolution, not "&TEXT(Settings!$B$4,"0%"),"")))
A17: =IF($B17="","",10) | D17: =IF($B17="","",$C17/1000) | E17: =IF($B17="","",$D17*$C$4) | F17: =IF($B17="","",IF($E17<=0,"NEITHER — zero",IF($E17>=Settings!$B$19,Settings!$B$6,IF($E17>Settings!$B$14,"NEITHER — over bench capacity",IF($E17>=2*Settings!$B$12,Settings!$B$11,"NEITHER — under bench resolution"))))) | G17: =IF($B17="","",IF($F17=Settings!$B$6,MAX(2*Settings!$B$7,Settings!$B$4*$E17),IF($F17=Settings!$B$11,MAX(2*Settings!$B$12,Settings!$B$4*$E17),""))) | H17: =IF($B17="","",IF(LEFT($F17,7)="NEITHER","Cannot be weighed — split it, premix it, or raise the batch size",IF($G17>Settings!$B$4*$E17+0.0001,"Held to the scale's resolution, not "&TEXT(Settings!$B$4,"0%"),"")))
